<?xml version="1.0" ?>
<!-- =================================================================================== -->
<!-- |    This document was autogenerated by xacro from Arm.xacro                      | -->
<!-- |    EDITING THIS FILE BY HAND IS NOT RECOMMENDED                                 | -->
<!-- =================================================================================== -->
<robot name="Arm">
  <material name="silver">
    <color rgba="0.700 0.700 0.700 1.000"/>
  </material>
  <transmission name="Revolute 3_tran">
    <type>transmission_interface/SimpleTransmission</type>
    <joint name="Revolute 3">
      <hardwareInterface>hardware_interface/EffortJointInterface</hardwareInterface>
    </joint>
    <actuator name="Revolute 3_actr">
      <hardwareInterface>hardware_interface/EffortJointInterface</hardwareInterface>
      <mechanicalReduction>1</mechanicalReduction>
    </actuator>
  </transmission>
  <transmission name="Slider 10_tran">
    <type>transmission_interface/SimpleTransmission</type>
    <joint name="Slider 10">
      <hardwareInterface>hardware_interface/EffortJointInterface</hardwareInterface>
    </joint>
    <actuator name="Slider 10_actr">
      <hardwareInterface>hardware_interface/EffortJointInterface</hardwareInterface>
      <mechanicalReduction>1</mechanicalReduction>
    </actuator>
  </transmission>
  <transmission name="Revolute 11_tran">
    <type>transmission_interface/SimpleTransmission</type>
    <joint name="Revolute 11">
      <hardwareInterface>hardware_interface/EffortJointInterface</hardwareInterface>
    </joint>
    <actuator name="Revolute 11_actr">
      <hardwareInterface>hardware_interface/EffortJointInterface</hardwareInterface>
      <mechanicalReduction>1</mechanicalReduction>
    </actuator>
  </transmission>
  <transmission name="Revolute 12_tran">
    <type>transmission_interface/SimpleTransmission</type>
    <joint name="Revolute 12">
      <hardwareInterface>hardware_interface/EffortJointInterface</hardwareInterface>
    </joint>
    <actuator name="Revolute 12_actr">
      <hardwareInterface>hardware_interface/EffortJointInterface</hardwareInterface>
      <mechanicalReduction>1</mechanicalReduction>
    </actuator>
  </transmission>
  <transmission name="Revolute 13_tran">
    <type>transmission_interface/SimpleTransmission</type>
    <joint name="Revolute 13">
      <hardwareInterface>hardware_interface/EffortJointInterface</hardwareInterface>
    </joint>
    <actuator name="Revolute 13_actr">
      <hardwareInterface>hardware_interface/EffortJointInterface</hardwareInterface>
      <mechanicalReduction>1</mechanicalReduction>
    </actuator>
  </transmission>
  <gazebo>
    <plugin filename="libgazebo_ros_control.so" name="control"/>
  </gazebo>
  <gazebo reference="base_link">
    <material>Gazebo/Silver</material>
    <mu1>0.2</mu1>
    <mu2>0.2</mu2>
    <selfCollide>true</selfCollide>
    <gravity>true</gravity>
  </gazebo>
  <gazebo reference="SAR_base_v5_1_1">
    <material>Gazebo/Silver</material>
    <mu1>0.2</mu1>
    <mu2>0.2</mu2>
    <selfCollide>true</selfCollide>
  </gazebo>
  <gazebo reference="7806K757_Thrust_Ball_Bearing_1_1">
    <material>Gazebo/Silver</material>
    <mu1>0.2</mu1>
    <mu2>0.2</mu2>
    <selfCollide>true</selfCollide>
  </gazebo>
  <gazebo reference="Movable_Claw_1_1">
    <material>Gazebo/Silver</material>
    <mu1>0.2</mu1>
    <mu2>0.2</mu2>
    <selfCollide>true</selfCollide>
  </gazebo>
  <gazebo reference="Iteration_1_v5_1_1">
    <material>Gazebo/Silver</material>
    <mu1>0.2</mu1>
    <mu2>0.2</mu2>
    <selfCollide>true</selfCollide>
  </gazebo>
  <gazebo reference="upperlink-updated_v4_1_1">
    <material>Gazebo/Silver</material>
    <mu1>0.2</mu1>
    <mu2>0.2</mu2>
    <selfCollide>true</selfCollide>
  </gazebo>
  <gazebo reference="lower_link_v39_1_1">
    <material>Gazebo/Silver</material>
    <mu1>0.2</mu1>
    <mu2>0.2</mu2>
    <selfCollide>true</selfCollide>
  </gazebo>
  <link name="base_link">
    <inertial>
      <origin rpy="0 0 0" xyz="0.05863104008803087 0.05615253071623694 -0.006755654576515199"/>
      <mass value="4.158186560469331"/>
      <inertia ixx="0.011476" ixy="3.8e-05" ixz="0.000125" iyy="0.024475" iyz="-0.000517" izz="0.028778"/>
    </inertial>
    <visual>
      <origin rpy="0 0 0" xyz="0 0 0"/>
      <geometry>
        <mesh filename="package://arm_description/meshes/base_link.stl" scale="0.001 0.001 0.001"/>
      </geometry>
      <material name="silver"/>
    </visual>
    <collision>
      <origin rpy="0 0 0" xyz="0 0 0"/>
      <geometry>
        <mesh filename="package://arm_description/meshes/base_link.stl" scale="0.001 0.001 0.001"/>
      </geometry>
    </collision>
  </link>
  <link name="SAR_base_v5_1_1">
    <inertial>
      <origin rpy="0 0 0" xyz="0.0032848504549910585 -0.0006395607193454139 0.054820590042331786"/>
      <mass value="1.2307761265001584"/>
      <inertia ixx="0.002811" ixy="-1e-06" ixz="-0.00014" iyy="0.002488" iyz="-2e-06" izz="0.003094"/>
    </inertial>
    <visual>
      <origin rpy="0 0 0" xyz="-0.00392 -0.065323 -0.046301"/>
      <geometry>
        <mesh filename="package://arm_description/meshes/SAR_base_v5_1_1.stl" scale="0.001 0.001 0.001"/>
      </geometry>
      <material name="silver"/>
    </visual>
    <collision>
      <origin rpy="0 0 0" xyz="-0.00392 -0.065323 -0.046301"/>
      <geometry>
        <mesh filename="package://arm_description/meshes/SAR_base_v5_1_1.stl" scale="0.001 0.001 0.001"/>
      </geometry>
    </collision>
  </link>
  <link name="7806K757_Thrust_Ball_Bearing_1_1">
    <inertial>
      <origin rpy="0 0 0" xyz="0.0010133938642193077 -0.000780780546192697 0.03812329599421187"/>
      <mass value="0.1611844314733173"/>
      <inertia ixx="4e-05" ixy="0.0" ixz="0.0" iyy="4e-05" iyz="-0.0" izz="7.3e-05"/>
    </inertial>
    <visual>
      <origin rpy="0 0 0" xyz="-0.00392 -0.065323 -0.018461"/>
      <geometry>
        <mesh filename="package://arm_description/meshes/7806K757_Thrust_Ball_Bearing_1_1.stl" scale="0.001 0.001 0.001"/>
      </geometry>
      <material name="silver"/>
    </visual>
    <collision>
      <origin rpy="0 0 0" xyz="-0.00392 -0.065323 -0.018461"/>
      <geometry>
        <mesh filename="package://arm_description/meshes/7806K757_Thrust_Ball_Bearing_1_1.stl" scale="0.001 0.001 0.001"/>
      </geometry>
    </collision>
  </link>
  <link name="Movable_Claw_1_1">
    <inertial>
      <origin rpy="0 0 0" xyz="0.03388991238375427 -0.01535562708110632 -0.006096587274510845"/>
      <mass value="0.8451631580038678"/>
      <inertia ixx="0.000295" ixy="-7.9e-05" ixz="0.000375" iyy="0.001215" iyz="3.2e-05" izz="0.001079"/>
    </inertial>
    <visual>
      <origin rpy="0 0 0" xyz="-0.662651 -0.02824 -0.400362"/>
      <geometry>
        <mesh filename="package://arm_description/meshes/Movable_Claw_1_1.stl" scale="0.001 0.001 0.001"/>
      </geometry>
      <material name="silver"/>
    </visual>
    <collision>
      <origin rpy="0 0 0" xyz="-0.662651 -0.02824 -0.400362"/>
      <geometry>
        <mesh filename="package://arm_description/meshes/Movable_Claw_1_1.stl" scale="0.001 0.001 0.001"/>
      </geometry>
    </collision>
  </link>
  <link name="Iteration_1_v5_1_1">
    <inertial>
      <origin rpy="0 0 0" xyz="0.04282769790372598 0.02491078728896462 -0.017160211944140247"/>
      <mass value="2.3017928452014056"/>
      <inertia ixx="0.015723" ixy="-0.001325" ixz="0.00084" iyy="0.002985" iyz="0.000506" izz="0.017484"/>
    </inertial>
    <visual>
      <origin rpy="0 0 0" xyz="-0.625809 -0.061331 -0.422763"/>
      <geometry>
        <mesh filename="package://arm_description/meshes/Iteration_1_v5_1_1.stl" scale="0.001 0.001 0.001"/>
      </geometry>
      <material name="silver"/>
    </visual>
    <collision>
      <origin rpy="0 0 0" xyz="-0.625809 -0.061331 -0.422763"/>
      <geometry>
        <mesh filename="package://arm_description/meshes/Iteration_1_v5_1_1.stl" scale="0.001 0.001 0.001"/>
      </geometry>
    </collision>
  </link>
  <link name="upperlink-updated_v4_1_1">
    <inertial>
      <origin rpy="0 0 0" xyz="0.2908732258181451 -0.04359455738158811 -0.1129536992000853"/>
      <mass value="1.2596257489986145"/>
      <inertia ixx="0.006044" ixy="0.000117" ixz="0.00924" iyy="0.02669" iyz="-5.3e-05" izz="0.023747"/>
    </inertial>
    <visual>
      <origin rpy="0 0 0" xyz="-0.232749 -0.105134 -0.580592"/>
      <geometry>
        <mesh filename="package://arm_description/meshes/upperlink-updated_v4_1_1.stl" scale="0.001 0.001 0.001"/>
      </geometry>
      <material name="silver"/>
    </visual>
    <collision>
      <origin rpy="0 0 0" xyz="-0.232749 -0.105134 -0.580592"/>
      <geometry>
        <mesh filename="package://arm_description/meshes/upperlink-updated_v4_1_1.stl" scale="0.001 0.001 0.001"/>
      </geometry>
    </collision>
  </link>
  <link name="lower_link_v39_1_1">
    <inertial>
      <origin rpy="0 0 0" xyz="0.09620535785687437 -0.051426121928776394 0.24687135655885625"/>
      <mass value="3.5085367595940884"/>
      <inertia ixx="0.069657" ixy="2.6e-05" ixz="-0.015569" iyy="0.073832" iyz="5e-05" izz="0.013911"/>
    </inertial>
    <visual>
      <origin rpy="0 0 0" xyz="-0.03273 -0.115646 -0.126985"/>
      <geometry>
        <mesh filename="package://arm_description/meshes/lower_link_v39_1_1.stl" scale="0.001 0.001 0.001"/>
      </geometry>
      <material name="silver"/>
    </visual>
    <collision>
      <origin rpy="0 0 0" xyz="-0.03273 -0.115646 -0.126985"/>
      <geometry>
        <mesh filename="package://arm_description/meshes/lower_link_v39_1_1.stl" scale="0.001 0.001 0.001"/>
      </geometry>
    </collision>
  </link>
  <link name="dummy_link">
    <!-- No geometry, mass, or inertia -->
  </link>
  <joint name="Rigid 2" type="fixed">
    <origin rpy="0 0 0" xyz="0.0 0.0 0.02784"/>
    <parent link="7806K757_Thrust_Ball_Bearing_1_1"/>
    <child link="SAR_base_v5_1_1"/>
  </joint>
  <joint name="Revolute 3" type="continuous">
    <origin rpy="0 0 0" xyz="0.00392 0.065323 0.018461"/>
    <parent link="base_link"/>
    <child link="7806K757_Thrust_Ball_Bearing_1_1"/>
    <axis xyz="0.0 -0.0 1.0"/>
  </joint>
  <joint name="Slider 10" type="prismatic">
    <origin rpy="0 0 0" xyz="0.036842 -0.033091 -0.022401"/>
    <parent link="Iteration_1_v5_1_1"/>
    <child link="Movable_Claw_1_1"/>
    <axis xyz="-0.00436 -0.99999 -0.0"/>
    <limit effort="100" lower="-0.06" upper="0.045" velocity="100"/>
  </joint>
  <joint name="Revolute 11" type="continuous">
    <origin rpy="0 0 0" xyz="0.39306 -0.043803 -0.157829"/>
    <parent link="upperlink-updated_v4_1_1"/>
    <child link="Iteration_1_v5_1_1"/>
    <axis xyz="0.927924 -0.004046 -0.372747"/>
  </joint>
  <joint name="Revolute 12" type="revolute">
    <origin rpy="0 0 0" xyz="0.200019 -0.010512 0.453607"/>
    <parent link="lower_link_v39_1_1"/>
    <child link="upperlink-updated_v4_1_1"/>
    <axis xyz="-0.00436 -0.99999 -0.0"/>
    <limit effort="100" lower="-0.872665" upper="0.174533" velocity="100"/>
  </joint>
  <joint name="Revolute 13" type="revolute">
    <origin rpy="0 0 0" xyz="0.02881 0.050323 0.080684"/>
    <parent link="SAR_base_v5_1_1"/>
    <child link="lower_link_v39_1_1"/>
    <axis xyz="-0.00436 -0.99999 -0.0"/>
    <limit effort="100" lower="-0.698132" upper="1.047198" velocity="100"/>
  </joint>
  <joint name="dummy_joint" type="fixed">
    <parent link="dummy_link" />
    <child link="base_link" />
    <origin rpy="0 0 0" xyz="0 0 0" />
   </joint>
</robot>
